<?xml version="1.0"?>
<robot xmlns:xacro="http://www.ros.org/wiki/xacro">

  <!-- Camera -->
  <link name="camera_motion_link"/>

  <link name="camera_link">
    <collision>
      <origin xyz="0 0 0" rpy="0 0 0"/>
      <geometry>
	      <box size="0.05 0.05 0.05"/>
      </geometry>
    </collision>

    <visual>
      <origin xyz="0 0 0" rpy="0 0 0"/>
      <geometry>
	      <box size="0.05 0.05 0.05"/>
      </geometry>
      <material name="red"/>
    </visual>

    <inertial>
      <mass value="1e-5" />
      <origin xyz="0 0 0" rpy="0 0 0"/>
      <inertia ixx="1e-6" ixy="0" ixz="0" iyy="1e-6" iyz="0" izz="1e-6" />
    </inertial>
  </link>

  <joint name="camera_motion_joint" type="revolute">
    <axis xyz="0 0 1" />
    <origin xyz="0 0 0" rpy="0 0 0"/>
    <parent link="world"/>
    <child link="camera_motion_link"/>
    <limit effort="87" lower="-3.14159" upper="3.14159" velocity="2.1750"/>
  </joint>

  <joint name="camera_joint" type="fixed">
    <axis xyz="0 0 1" />
    <origin xyz="2 0 0.5" rpy="0 0 ${PI}"/>
    <parent link="camera_motion_link"/>
    <child link="camera_link"/>
  </joint>
  
  <link name="camera_link_optical">
  </link>
  <joint name="camera_optical_joint" type="fixed">
    <origin xyz="0 0 0" rpy="${-PI/2} 0 ${PI/2}"/>
    <parent link="camera_link"/>
    <child link="camera_link_optical"/>
  </joint>

</robot>
