<?xml version="1.0"?>
<sdf version='1.6'>
  <model name="panda">
  <pose>0 0 0 0 0 0</pose>
    <link name='base_link'/>
 
    <link name='panda_link0'>
      <pose>0 0 0 0 0 0</pose>
      <inertial>
        <pose>0 0 0 0 0 0</pose>
        <inertia>
          <ixx>1</ixx>
          <ixy>0</ixy>
          <ixz>0</ixz>
          <iyy>1</iyy>
          <iyz>0</iyz>
          <izz>1</izz>
        </inertia>
        <mass>0</mass>
      </inertial>
      <collision name='panda_link0_collision'>
        <pose>0 0 0 0 0 0</pose>
        <geometry>
          <mesh>
            <scale>1 1 1</scale>
            <uri>model://panda/meshes/collision/link0.obj</uri>
          </mesh>
        </geometry>
      </collision>
      <visual name='panda_link0_visual'>
        <pose>0 0 0 0 0 0</pose>
        <geometry>
          <mesh>
            <scale>1 1 1</scale> 
            <uri>model://panda/meshes/visual/link0.dae</uri>
          </mesh>
        </geometry>
        <material>
          <script>
            <name>Gazebo/DarkGrey</name>
            <uri>__default__</uri>
          </script>
        </material>
      </visual>
    </link>
    
    <link name='panda_link1'>
      <pose>0 0 0.333 0 0 0</pose>
      <inertial>
        <pose>0 0 0 0 0 0</pose>
        <inertia>
          <ixx>1</ixx>
          <ixy>0</ixy>
          <ixz>0</ixz>
          <iyy>1</iyy>
          <iyz>0</iyz>
          <izz>1</izz>
        </inertia>
        <mass>0</mass>
      </inertial>
      <collision name='panda_link1_collision'>
        <pose>0 0 0 0 0 0</pose>
        <geometry>
          <mesh>
            <scale>1 1 1</scale>
            <uri>model://panda/meshes/collision/link1.obj</uri>
          </mesh>
        </geometry>
      </collision>
      <visual name='panda_link1_visual'>
        <pose>0 0 0 0 0 0</pose>
        <geometry>
          <mesh>
            <scale>1 1 1</scale> 
            <uri>model://panda/meshes/visual/link1.dae</uri>
          </mesh>
        </geometry>
        <material>
          <script>
            <name>Gazebo/DarkGrey</name>
            <uri>__default__</uri>
          </script>
        </material>
      </visual>
    </link>
    
    <link name='panda_link2'>
      <pose>0 0 0.333 -1.57079632679 0 0</pose>
      <inertial>
        <pose>0 0 0 0 0 0</pose>
        <inertia>
          <ixx>1</ixx>
          <ixy>0</ixy>
          <ixz>0</ixz>
          <iyy>1</iyy>
          <iyz>0</iyz>
          <izz>1</izz>
        </inertia>
        <mass>0</mass>
      </inertial>
      <collision name='panda_link2_collision'>
        <pose>0 0 0 0 0 0</pose>
        <geometry>
          <mesh>
            <scale>1 1 1</scale>
            <uri>model://panda/meshes/collision/link2.obj</uri>
          </mesh>
        </geometry>
      </collision>
      <visual name='panda_link2_visual'>
        <pose>0 0 0 0 0 0</pose>
        <geometry>
          <mesh>
            <scale>1 1 1</scale> 
            <uri>model://panda/meshes/visual/link2.dae</uri>
          </mesh>
        </geometry>
        <material>
          <script>
            <name>Gazebo/DarkGrey</name>
            <uri>__default__</uri>
          </script>
        </material>
      </visual>
    </link>

    <link name='panda_link3'>
      <pose>0 0 0.649 0 0 0</pose>
      <inertial>
        <pose>0 0 0 0 0 0</pose>
        <inertia>
          <ixx>1</ixx>
          <ixy>0</ixy>
          <ixz>0</ixz>
          <iyy>1</iyy>
          <iyz>0</iyz>
          <izz>1</izz>
        </inertia>
        <mass>0</mass>
      </inertial>
      <collision name='panda_link3_collision'>
        <pose>0 0 0 0 0 0</pose>
        <geometry>
          <mesh>
            <scale>1 1 1</scale>
            <uri>model://panda/meshes/collision/link3.obj</uri>
          </mesh>
        </geometry>
      </collision>
      <visual name='panda_link3_visual'>
        <pose>0 0 0 0 0 0</pose>
        <geometry>
          <mesh>
            <scale>1 1 1</scale> 
            <uri>model://panda/meshes/visual/link3.dae</uri>
          </mesh>
        </geometry>
        <material>
          <script>
            <name>Gazebo/DarkGrey</name>
            <uri>__default__</uri>
          </script>
        </material>
      </visual>
    </link>

    <link name='panda_link4'>
    <pose>0.0825 0 0.649 1.57079632679 0 0</pose>
    <inertial>
        <pose>0 0 0 0 0 0</pose>
        <inertia>
          <ixx>1</ixx>
          <ixy>0</ixy>
          <ixz>0</ixz>
          <iyy>1</iyy>
          <iyz>0</iyz>
          <izz>1</izz>
        </inertia>
        <mass>0</mass>
      </inertial>
      <collision name='panda_link4_collision'>
        <pose>0 0 0 0 0 0</pose>
        <geometry>
          <mesh>
            <scale>1 1 1</scale>
            <uri>model://panda/meshes/collision/link4.obj</uri>
          </mesh>
        </geometry>
      </collision>
      <visual name='panda_link4_visual'>
        <pose>0 0 0 0 0 0</pose>
        <geometry>
          <mesh>
            <scale>1 1 1</scale> 
            <uri>model://panda/meshes/visual/link4.dae</uri>
          </mesh>
        </geometry>
        <material>
          <script>
            <name>Gazebo/DarkGrey</name>
            <uri>__default__</uri>
          </script>
        </material>
      </visual>
    </link>

    <link name='panda_link5'>
      <pose>0 0 1.033 0 0 0</pose>
      <inertial>
        <pose>0 0 0 0 0 0</pose>
        <inertia>
          <ixx>1</ixx>
          <ixy>0</ixy>
          <ixz>0</ixz>
          <iyy>1</iyy>
          <iyz>0</iyz>
          <izz>1</izz>
        </inertia>
        <mass>0</mass>
      </inertial>
      <collision name='panda_link5_collision'>
        <pose>0 0 0 0 0 0</pose>
        <geometry>
          <mesh>
            <scale>1 1 1</scale>
            <uri>model://panda/meshes/collision/link5.obj</uri>
          </mesh>
        </geometry>
      </collision>
      <visual name='panda_link5_visual'>
        <pose>0 0 0 0 0 0</pose>
        <geometry>
          <mesh>
            <scale>1 1 1</scale> 
            <uri>model://panda/meshes/visual/link5.dae</uri>
          </mesh>
        </geometry>
        <material>
          <script>
            <name>Gazebo/DarkGrey</name>
            <uri>__default__</uri>
          </script>
        </material>
      </visual>
    </link>
    <link name='panda_link6'>
      <pose>0 0 1.033 1.57079632679 0 0</pose>
      <inertial>
        <pose>0 0 0 0 0 0</pose>
        <inertia>
          <ixx>1</ixx>
          <ixy>0</ixy>
          <ixz>0</ixz>
          <iyy>1</iyy>
          <iyz>0</iyz>
          <izz>1</izz>
        </inertia>
        <mass>0</mass>
      </inertial>
      <collision name='panda_link6_collision'>
        <pose>0 0 0 0 0 0</pose>
        <geometry>
          <mesh>
            <scale>1 1 1</scale>
            <uri>model://panda/meshes/collision/link6.obj</uri>
          </mesh>
        </geometry>
      </collision>
      <visual name='panda_link6_visual'>
        <pose>0 0 0 0 0 0</pose>
        <geometry>
          <mesh>
            <scale>1 1 1</scale> 
            <uri>model://panda/meshes/visual/link6.dae</uri>
          </mesh>
        </geometry>
        <material>
          <script>
            <name>Gazebo/DarkGrey</name>
            <uri>__default__</uri>
          </script>
        </material>
      </visual>
    </link>
    <link name='panda_link7'>
      <pose>0.088 0 1.033 3.14159 0 0</pose>
      <inertial>
        <pose>0 0 0 0 0 0</pose>
        <inertia>
          <ixx>1</ixx>
          <ixy>0</ixy>
          <ixz>0</ixz>
          <iyy>1</iyy>
          <iyz>0</iyz>
          <izz>1</izz>
        </inertia>
        <mass>0</mass>
      </inertial>
      <collision name='panda_link7_collision'>
        <pose>0 0 0 0 0 0</pose>
        <geometry>
          <mesh>
            <scale>1 1 1</scale>
            <uri>model://panda/meshes/collision/link7.obj</uri>
          </mesh>
        </geometry>
      </collision>
      <visual name='panda_link7_visual'>
        <pose>0 0 0 0 0 0</pose>
        <geometry>
          <mesh>
            <scale>1 1 1</scale> 
            <uri>model://panda/meshes/visual/link7.dae</uri>
          </mesh>
        </geometry>
        <material>
          <script>
            <name>Gazebo/DarkGrey</name>
            <uri>__default__</uri>
          </script>
        </material>
      </visual>
    </link>
    <link name='panda_link8'>
      <pose>0.088 0 0.926 3.14159 0 0.785398163397</pose>
    </link>

    <link name='panda_hand'>
      <pose>0.088 0 0.926 3.14159 0 0.785398163397</pose>
      <inertial>
        <pose>0 0 0 0 0 0</pose>
        <inertia>
          <ixx>1</ixx>
          <ixy>0</ixy>
          <ixz>0</ixz>
          <iyy>1</iyy>
          <iyz>0</iyz>
          <izz>1</izz>
        </inertia>
        <mass>0</mass>
      </inertial>
      <collision name='panda_hand_collision'>
        <pose>0 0 0 0 0 0</pose>
        <geometry>
          <mesh>
            <scale>1 1 1</scale>
            <uri>model://panda/meshes/collision/hand.obj</uri>
          </mesh>
        </geometry>
      </collision>
      <visual name='panda_hand_visual'>
        <pose>0 0 0 0 0 0</pose>
        <geometry>
          <mesh>
            <scale>1 1 1</scale> 
            <uri>model://panda/meshes/visual/hand.dae</uri>
          </mesh>
        </geometry>
        <material>
          <script>
            <name>Gazebo/DarkGrey</name>
            <uri>__default__</uri>
          </script>
        </material>
      </visual>
    </link>
    <link name='panda_leftfinger'>
      <pose>0.088 0 0.8676926 3.14159 0 0.785398163397</pose>
      <inertial>
        <pose>0 0 0 0 0 0</pose>
        <inertia>
          <ixx>1</ixx>
          <ixy>0</ixy>
          <ixz>0</ixz>
          <iyy>1</iyy>
          <iyz>0</iyz>
          <izz>1</izz>
        </inertia>
        <mass>0</mass>
      </inertial>
      <collision name='panda_leftfinger_collision'>
        <pose>0 0 0 0 0 0</pose>
        <geometry>
          <mesh>
            <scale>1 1 1</scale>
            <uri>model://panda/meshes/collision/finger.obj</uri>
          </mesh>
        </geometry>
      </collision>
      <visual name='panda_leftfinger_visual'>
        <pose>0 0 0 0 0 0</pose>
        <geometry>
          <mesh>
            <scale>1 1 1</scale> 
            <uri>model://panda/meshes/visual/finger.dae</uri>
          </mesh>
        </geometry>
        <material>
          <script>
            <name>Gazebo/DarkGrey</name>
            <uri>__default__</uri>
          </script>
        </material>
      </visual>
    </link>

    <joint name='base_joint' type='fixed'>
      <parent>base_link</parent>
      <child>panda_link0</child>
      <pose>0 0 0 0 0 0</pose>
      <axis>
        <xyz>0 0 1</xyz>
      </axis>
    </joint>
    
    <joint name='panda_joint1' type='revolute'>
      <parent>panda_link0</parent>
      <child>panda_link1</child>
      <pose>0 0 -0.19 0 0 0</pose>
      <axis>
        <xyz>0 0 1</xyz>
        <limit>
          <lower>-2.9671</lower>
          <upper>2.9671</upper>
        </limit>
        <dynamics>
          <damping>1.000</damping>
        </dynamics>
      </axis>
    </joint>

    <joint name='panda_joint2' type='revolute'>
      <parent>panda_link1</parent>
      <child>panda_link2</child>
      <pose>0 0 0 0 0 0</pose>
      <axis>
        <xyz>0 0 1</xyz>
        <limit>
          <lower>-2.9671</lower>
          <upper>2.9671</upper>
        </limit>
        <dynamics>
          <damping>1.000</damping>
        </dynamics>
      </axis>
    </joint>

    <joint name='panda_joint3' type='revolute'>
      <parent>panda_link2</parent>
      <child>panda_link3</child>
      <pose>0 0 -0.12 0 0 0</pose>
      <axis>
        <xyz>0 0 1</xyz>
        <limit>
          <lower>-2.9671</lower>
          <upper>2.9671</upper>
        </limit>
        <dynamics>
          <damping>1.000</damping>
        </dynamics>
      </axis>
    </joint>
    <joint name='panda_joint4' type='revolute'>
      <parent>panda_link3</parent>
      <child>panda_link4</child>
      <pose>0 0 0 0 0 0</pose>
      <axis>
        <xyz>0 0 1</xyz>
        <limit>
          <lower>-2.9671</lower>
          <upper>2.9671</upper>
        </limit>
        <dynamics>
          <damping>1.000</damping>
        </dynamics>
      </axis>
    </joint>
    <joint name='panda_joint5' type='revolute'>
      <parent>panda_link4</parent>
      <child>panda_link5</child>
      <pose>0 0 -0.26 0 0 0</pose>
      <axis>
        <xyz>0 0 1</xyz>
        <limit>
          <lower>-2.9671</lower>
          <upper>2.9671</upper>
        </limit>
        <dynamics>
          <damping>1.000</damping>
        </dynamics>
      </axis>
    </joint>
    <joint name='panda_joint6' type='revolute'>
      <parent>panda_link5</parent>
      <child>panda_link6</child>
      <pose>0 0 0 0 0 0</pose>
      <axis>
        <xyz>0 0 1</xyz>
        <limit>
          <lower>-2.9671</lower>
          <upper>2.9671</upper>
        </limit>
        <dynamics>
          <damping>1.000</damping>
        </dynamics>
      </axis>
    </joint>
    <joint name='panda_joint7' type='revolute'>
      <parent>panda_link6</parent>
      <child>panda_link7</child>
      <pose>0 0 0.05 0 0 0</pose>
      <axis>
        <xyz>0 0 1</xyz>
        <limit>
          <lower>-2.9671</lower>
          <upper>2.9671</upper>
        </limit>
        <dynamics>
          <damping>1.000</damping>
        </dynamics>
      </axis>
    </joint>
    <joint name='panda_joint8' type='fixed'>
      <parent>panda_link7</parent>
      <child>panda_link8</child>
      <pose>0 0 0 0 0 0</pose>
      <axis>
        <xyz>0 0 1</xyz>
      </axis>
    </joint>
    <joint name='panda_hand_joint' type='fixed'>
      <parent>panda_link8</parent>
      <child>panda_hand</child>
      <pose>0 0 0 0 0 0</pose>
      <axis>
        <xyz>0 0 1</xyz>
      </axis>
    </joint>
    <joint name='panda_finger_joint1' type='prismatic'>
      <parent>panda_hand</parent>
      <child>panda_leftfinger</child>
      <pose>0 0 0.0 0 0 0</pose>
      <axis>
        <xyz>0 1 0</xyz>
        <limit>
          <lower>0</lower>
          <upper>0.04</upper>
        </limit>
        <dynamics>
          <damping>1.000</damping>
        </dynamics>
      </axis>
    </joint>
  </model>
</sdf>